Workbook

Sheet Cennik Produkcja 
A2: Zdjęcie | B2: Nazwa | C2: Kalkulacja | H2: Rabat :
B5: Przepustnica wielopłaszczyznowa | D5: Szerokość B/mm | E5: Wysokość H/mm | G5: Cena netto
D6: 350 | E6: 250 | G6: =Przepustnice!F39 -> 234.13019 | H6: N
D7: Typ R/B | G7: Cena wyprodukowania | H7: =(G6-G8)/G8 -> 2.5264316
D8: B | G8: =Przepustnice!F37 -> 66.392947
D9: Szerokość B/mm | E9: Wysokość H/mm | G9: Cena netto
D10: 250 | E10: 200 | G10: =Przepustnice!F66 -> 82.837092 | H10: N
B11: Przepustnica jednopłaszczyznowa | D11: Długość L/mm | G11: Cena wyprodukowania | H11: =(G10-G12)/G12 -> 1.2242584
D12: 250 | G12: =Przepustnice!F64 -> 37.242567
D15: Szerokość B/mm | E15: Wysokość H/mm | F15: ZA RAL | G15: Cena netto
B16: Czerpnia ścienna standardowa | D16: 250 | E16: 150 | F16: =IF((D16*E16*4)/1000000 <= 1, 'Ceny składowe'!C90, ((D16*E16*4)/1000000) * 'Ceny składowe'!C90) -> 70 | G16: ='Czerpnia ścienna'!M22 -> 69.35 | H16: N
G17: Cena wyprodukowania | H17: =(G16-G18)/G18 -> 0.73485388
G18: ='Czerpnia ścienna'!F23 -> 39.974548
D20: Wymiar A | E20: Wymiar B | G20: Cena netto
D21: 550 | E21: 550 | G21: ='Czerpnia dachowa lamelowa'!F38 -> 702.441 | H21: N
B22: Czerpnia/wyrzutnia lamelowa | D22: Wysokość h(e)/mm | E22: Wysokość H/mm | G22: Cena wyprodukowania | H22: =(G21-G23)/G23 -> 1.2319934
D23: 500 | E23: 800 | G23: ='Czerpnia dachowa lamelowa'!F41 -> 314.71463
D24: ilość lameli | E24: wysokość stopy
D25: =((ROUND(D23,0.1))/70) -> 7.1428571 | E25: =E23-D23 -> 300
D27: Wymiar A | E27: Wymiar B | G27: Cena netto
D28: 500 | E28: 500 | G28: ='Czerpnia dachowa lamelowa'!F85 -> 657.972 | H28: N
B29: Czerpnia/wyrzutnia lamelowa | D29: Wysokość h(stopka)/mm | E29: ilość lameli | F29: wysokość lam. | G29: Cena wyprodukowania | H29: =(G28-G30)/G30 -> 1.411989
B30: (ALNOR) | D30: 300 | E30: ='Czerpnia dachowa lamelowa'!G55 -> 7 | F30: =E30*70 -> 490 | G30: ='Czerpnia dachowa lamelowa'!F88 -> 272.79229
D34: Wymiar A | E34: Wymiar B | G34: Cena netto
D35: 500 | E35: 500 | G35: ='Czerpnia dachowa lamelowa'!U85 -> 616.76 | H35: N
B36: Czerpnia/wyrzutnia lamelowa | D36: Wysokość h(stopka)/mm | E36: ilość lameli | F36: wysokość lam. | G36: Cena wyprodukowania | H36: =(G35-G37)/G37 -> 1.6799894
B37: (SMAY) | D37: 300 | E37: ='Czerpnia dachowa lamelowa'!V55 -> 5 | F37: =E37*70 -> 350 | G37: ='Czerpnia dachowa lamelowa'!U88 -> 230.13524
D41: Wymiar A | E41: Wymiar B | G41: Cena netto
D42: 400 | E42: 400 | G42: =Wyrzutnie!N77 -> 651.05298 | H42: N
B43: Wyrzutnia dachowa WDQ-E | E43: Długość L/mm | G43: Cena wyprodukowania | H43: =(G42-G44)/G44 -> 3.3663974
B44: typ-E | E44: =Wyrzutnie!K45 -> 890 | G44: =Wyrzutnie!N81 -> 149.1053
D49: Szerokość B/mm | E49: Wysokość H/mm | G49: Cena netto
B50: Tłumik akustyczny prostokątny | D50: 1400 | E50: 300 | G50: ='Tłumik prostokątny'!F44 -> 1131.9408 | H50: N
D51: Długość L/mm | E51: Rozmiar kulis | F51: Ilość kulis | G51: Cena wyprodukowania | H51: =(G50-G52)/G52 -> 1.2352504
D52: 1000 | E52: =IF(D50<=1000,100,IF(D50>1000,200)) -> 200 | F52: =IF(D50<=300,1,IF(D50<=500,2,IF(D50<=700,3,IF(D50<=900,4,IF(D50<=1000,5,IF(D50<=1300,3,IF(D50<=1700,4,IF(D50<=2000,5,IF(D50<=2500,6,IF(D50<=3000,7)))))))))) -> 4 | G52: ='Tłumik prostokątny'!F48 -> 506.40445
D56: Szerokość B/mm | E56: Wysokość H/mm | G56: Cena netto
D57: 550 | E57: 300 | G57: ='Tłumik prostokątny'!F93 -> 493.45325 | H57: N
B58: Tłumik akustyczny prostokątny | D58: Długość L/mm | E58: Rozmiar kulis | F58: Ilość kulis | G58: Cena wyprodukowania | H58: =(G57-G59)/G59 -> 2.7445132
B59: niestandarowe kulisy | D59: 1000 | E59: 100 | F59: 2 | G59: ='Tłumik prostokątny'!F97 -> 131.78035
G60: Cena netto kulisy
...

Sheet Ceny składowe
A1: aktualizacja cen (21.09.2026)
A4: KOD OPTIMA | B4: Materiał | C4: cena jedn. | D4: j.m
A6: BLACHA0,60X1500 | B6: Blacha 0,6 | C6: 4.3 | D6: kg
A7: BLACHA0,80X1500 | B7: Blacha 0,8 | C7: 4.2 | D7: kg
A8: BLACHA0,90X1500 | B8: Blacha 0,9 | C8: 4.2 | D8: kg
A9: BLACHA0.50X137 | B9: Blacha 0,5 spiro II Gat. | C9: 4.3 | D9: kg
A10: BLACHA0,5X2000X1000NIERDZ | B10: Blacha 0,5 nierdzewna | C10: 170 | D10: arkusz | E10: (2m2)
A11: BLACHA0,7X2500X1250NIERDZ | B11: Blacha 0,7 nierdzewna | C11: 360 | D11: arkusz | E11: (3,125m2)
A12: KAIFLEX/ST/25/SAMOPRZYLEP | B12: Izolacja kauczukowa | C12: 45.27 | D12: m2
A13: KAUCZUK 10MM | B13: Izolacja kauczukowa | C13: 26.81 | D13: m2 | E13: (20m2)
A14: KAUCZUK 13MM | B14: Izolacja kauczukowa | C14: 28.21 | D14: m2 | E14: (11m2)
A15: KAUCZUK 19MM | B15: Izolacja kauczukowa | C15: 38.35 | D15: m2 | E15: (8m2)
A16: INSUL-ROLL 32 | B16: Izolacja kauczukowa | C16: 57.07 | D16: m2 | E16: (4m2)
A17: KOŁNIERZAMORTYZUJACY (CN) | B17: Taśma amortyzująca | C17: 3.06 | D17: mb
A18: KOŁOZĘBATE | B18: Koło zębate | C18: 1.06 | D18: szt.
A19: QPL-8 | B19: Łożysko | C19: 0.55 | D19: szt.
A20: NAROŻNIK-K20 | B20: Narożnik 20mm | C20: 0.27 | D20: szt.
A21: NAROŻNIKNIERDZ20 | B21: Narożnik 20mm nierdzewny | C21: 2.7 | D21: szt.
A22: NAROŻNIK-K30 | B22: Narożniki 30mm | C22: 0.75 | D22: szt.
A23: NAROŻNIKNIERDZ30 | B23: Narożniki 30mm nierdzewny | C23: 5.1 | D23: szt.
A24: NAROŻNIKCZERPNI | B24: Narożnik czerpni | C24: 1.1 | D24: szt.
A25: NITONAKRĘTKA M6 | B25: Nitonakrętka M6 | C25: 0.16 | D25: szt.
A26: NITONAKRĘTKA M8 | B26: Nitonakrętka M8 | C26: 0.19 | D26: szt.
A27: NITONAKRĘTKA M10 | B27: Nitonakrętka M10 | C27: 0.3 | D27: szt.
A28: QOTD | B28: Oś długa | C28: 0.57 | D28: szt.
... A39: PROFILCZERPNIP | B39: Profil ramy czerpni punktowany | C39: 11.9 | D39: mb
A40: PROFILPRZEPUSTNICAWILOPŁ | B40: Profil przepustnicy | C40: 22.9 | D40: mb | E40: (1,7mb) | F40: PROFIL ALU.PIÓRO
A41: SIATKACASANET19X19 L=1500 | B41: Siatka 19x19 1,5m | C41: 24.39 | D41: mb
A42: SIATKACASANET19X19 | B42: Siatka 19x19 1m | C42: 17.2 | D42: mb/m2
A43: WŁOKNINAFILTRG3/2000/20000 | B43: Włóknina filtracyjna | C43: 5.79 | D43: m2 | E43: 40m2 | F43: doliczony koszt dostawy 100zł do rolki
A44: ZAWIASTAŚMOWY | B44: Zawias taśmowy | C44: 8.06 | D44: szt.
A45: ZAMEKDOPRZEPJEDN | B45: Zamek do przepustnic jednopłasz. | C45: 7 | D45: szt.
A46: ZAMEKDOPRZEPOKRĄGŁYCH | B46: Zamek do przepustnic jednopłasz. | C46: 4.9 | D46: szt.
A47: ZAMEDOPRZEPUSTNIC | B47: Zamek wielopłaszczyznowych duży | C47: 6.9 | D47: szt.
A48: ZAMEK GOEBEL 40/F | B48: Zamek Goebel | C48: 3.46 | D48: szt.
A49: VENTILAM ALU 20MM | B49: wełna do tłumików okrągłych 20mm | C49: 11.54 | D49: m2
A50: VENTILAM ALU 30MM | B50: wełna do tłumików okrągłych 30mm | C50: 14.73 | D50: m2
A51: VENTILAM ALU 40MM | B51: Wełna do tłumików okrągłych 40mm | C51: 18.1 | D51: m2
A52: VENTILAM ALU 50MM | B52: Wełna do tłumików okrągłych 50mm | C52: 21.56 | D52: m2 | E52: 6m2
A53: VENTILAM ALU PLUS 20MM | B53: Ventilam Alu Plus 20mm | C53: 20.13 | D53: m2 | E53: 12m2
...

Sheet Kanał osiatkowany
B4: kanał osiatkowany | K4: kanał wentylacjyjny
B5: A | D5: ='Cennik Produkcja '!D354 -> 680 | K5: A | M5: ='Cennik Produkcja '!D424 -> 200
B6: B | D6: ='Cennik Produkcja '!E354 -> 680 | K6: B | M6: ='Cennik Produkcja '!E424 -> 200
B7: L | D7: ='Cennik Produkcja '!D356 -> 100 | K7: L | M7: ='Cennik Produkcja '!D426 -> 1500
B10: Pole blachy | D10: =((D5+D5+D6+D6)*D7)/1000000 -> 0.272 | E10: m2 | G10: =IF(OR(F6>1000,F7>1000),4,0.0001) -> 0.0001 | K10: Pole blachy | M10: =((M5+M5+M6+M6)*M7)/1000000 -> 1.2 | N10: m2 | O10: ='Cennik Produkcja '!F424 -> 1.2 | P10: m2
B11: Pole siatki | D11: =D5*D6/1000000 -> 0.4624 | E11: m2 | K11: Ramka 20 | M11: =(M5+M5+M6+M6)/1000 -> 0.8 | N11: mb
B12: Ramka 20 | D12: =(D5+D5+D6+D6)/1000 -> 2.72 | E12: mb | K12: Ramka 30 | M12: =M11 -> 0.8 | N12: mb
B13: Ramka 30 | D13: =D12 -> 2.72 | E13: mb
K14: Blacha 0,6 | M14: =M10*4.8 -> 5.76 | N14: kg
B15: Blacha 0,6 | D15: =D10*4.8 -> 1.3056 | E15: kg | K15: Blacha 0,8 | M15: =M10*6.4 -> 7.68 | N15: kg
B16: Blacha 0,8 | D16: =D10*6.4 -> 1.7408 | E16: kg | K16: Blacha 0,9 | M16: =M10*7.2 -> 8.64 | N16: kg
B17: Blacha 0,9 | D17: =D10*7.2 -> 1.9584 | E17: kg
A20: KOD OPTIMA | B20: Zapotrzebowanie materiału | C20: ilość | E20: cena jednostkowa | F20: Wartość | J20: KOD OPTIMA | K20: Zapotrzebowanie materiału | L20: ilość | N20: cena jednostkowa | O20: Wartość
A21: BLACHA0,60X1500 | B21: blacha 0,6 | C21: =IF(D5<=1000,D15,0.0001) -> 1.3056 | D21: kg | E21: ='Ceny składowe'!C6 -> 4.3 | F21: =C21*E21 -> 5.61408 | J21: BLACHA0,60X1500 | K21: blacha 0,6 | L21: =IF(M5<=1000,M14,0.0001) -> 5.76 | M21: kg | N21: ='Ceny składowe'!C6 -> 4.3 | O21: =L21*N21 -> 24.768
A22: BLACHA0,80X1500 | B22: blacha 0,8 | C22: =IF(AND(D5>1000,D5<=1400),D16,0.0001) -> 0.0001 | D22: kg | E22: ='Ceny składowe'!C7 -> 4.2 | F22: =C22*E22 -> 0.00042 | J22: BLACHA0,80X1500 | K22: blacha 0,8 | L22: =IF(AND(M5>1000,M5<=1400),M15,0.0001) -> 0.0001 | M22: kg | N22: ='Ceny składowe'!C7 -> 4.2 | O22: =L22*N22 -> 0.00042
A23: BLACHA0,90X1500 | B23: blacha 0,9 | C23: =IF(D5>1400,D17,0.0001) -> 0.0001 | D23: kg | E23: ='Ceny składowe'!C8 -> 4.2 | F23: =C23*E23 -> 0.00042 | J23: BLACHA0,90X1500 | K23: blacha 0,9 | L23: =IF(M5>1400,M16,0.0001) -> 0.0001 | M23: kg | N23: ='Ceny składowe'!C8 -> 4.2 | O23: =L23*N23 -> 0.00042
A24: SIATKACASANET19X19 | B24: siatkacasanet | C24: =D11 -> 0.4624 | D24: m2 | E24: ='Ceny składowe'!C42 -> 17.2 | F24: =C24*E24 -> 7.95328 | J24: PROFILRAMKI20-P | K24: profilramki 20 | L24: =IF(OR(M5>1000,M6>1000),0.0001,M11) -> 0.8 | M24: mb | N24: ='Ceny składowe'!C34 -> 1.89 | O24: =L24*N24 -> 1.512
A25: PROFILRAMKI20-P | B25: profilramki 20 | C25: =IF(OR(D5>1000,D6>1000),0.0001,D12) -> 2.72 | D25: mb | E25: ='Ceny składowe'!C34 -> 1.89 | F25: =C25*E25 -> 5.1408 | J25: PROFILRAMKI30-P | K25: profilramki 30 | L25: =IF(OR(M5>1000,M6>1000),M12,0.0001) -> 0.0001 | M25: mb | N25: ='Ceny składowe'!C36 -> 2.92 | O25: =L25*N25 -> 0.000292
A26: PROFILRAMKI30-P | B26: profilramki 30 | C26: =IF(OR(D5>1000,D6>1000),D13,0.0001) -> 0.0001 | D26: mb | E26: ='Ceny składowe'!C36 -> 2.92 | F26: =C26*E26 -> 0.000292 | J26: NAROŻNIK-K20 | K26: narożnik 20 | L26: =IF(OR(M5>1000,M6>1000),0.0001,4) -> 4 | M26: szt. | N26: ='Ceny składowe'!C20 -> 0.27 | O26: =L26*N26 -> 1.08
A27: NAROŻNIK-K20 | B27: narożnik 20 | C27: =IF(OR(D5>1000,D6>1000),0.0001,4) -> 4 | D27: szt. | E27: ='Ceny składowe'!C20 -> 0.27 | F27: =C27*E27 -> 1.08 | J27: NAROŻNIK-K30 | K27: narożnik 30 | L27: =IF(OR(M5>1000,M6>1000),4,0.0001) -> 0.0001 | M27: szt. | N27: ='Ceny składowe'!C22 -> 0.75 | O27: =L27*N27 -> 7.5e-05
A28: NAROŻNIK-K30 | B28: narożnik 30 | C28: =IF(OR(D5>1000,D6>1000),4,0.0001) -> 0.0001 | D28: szt. | E28: ='Ceny składowe'!C22 -> 0.75 | F28: =C28*E28 -> 7.5e-05
L30: epoksyd | M30: ='Cennik Produkcja '!F426 -> NIE
E31: Koszt | F31: =SUM(F21:F30) -> 19.789367 | L31: epoksyd | M31: =O10*'Ceny składowe'!C91 -> 90 | N31: Koszt | O31: =SUM(O21:O27) -> 27.361207
E33: Cena H3 | F33: =F31*3.8 -> 75.199595 | N33: Cena ocynk | O33: =(_xlfn.IFS(MAX(M5,M6)<=1000, 'Ceny składowe'!C80, MAX(M5,M6)<=1400, 'Ceny składowe'!C81, MAX(M5,M6)<=2000, 'Ceny składowe'!C82, MAX(M5,M6)>2000, 'Ceny składowe'!C83)*O10 + IF(M30="TAK", M31, 0)) -> 63.48
E34: Narzut | F34: =(F33-F31)/F31 -> 2.8 | N34: Narzut | O34: =(O33-O31)/O31 -> 1.3200731
N36: Cena nierdzewka | O36: =(_xlfn.IFS(MAX(M5,M6)<=1000, 'Ceny składowe'!C84,MAX(M5,M6)<=1400, 'Ceny składowe'!C85,MAX(M5,M6)<=2000, 'Ceny składowe'!C86,MAX(M5,M6)>2000, 0)*O10) -> 372

Sheet Ramka do kanałów
E4: Ramka | L4: Kątownik, Ceownik
E6: A | F6: ='Cennik Produkcja '!D319 -> 470 | G6: mm | L6: Szerokość | M6: ='Cennik Produkcja '!D383 -> 30 | N6: mm
E7: B | F7: ='Cennik Produkcja '!E319 -> 470 | G7: mm | L7: Wysokość | M7: ='Cennik Produkcja '!E383 -> 30 | N7: mm
L8: Długość L | M8: ='Cennik Produkcja '!D385 -> 1500 | N8: mm
K9: profil: | L9: ='Cennik Produkcja '!E385 -> Kątownik
E10: Narożnik 20 | F10: 4 | G10: szt | K10: blacha: | L10: ='Cennik Produkcja '!F385 -> 0.8 | M10: =L10*8 -> 6.4
E11: Narożnik 30 | F11: 4 | G11: szt
E12: Profil ramki K20 | F12: =((F6*2)+(F7*2))/1000 -> 1.88 | G12: mb | K12: powierzchnia blachy (kątownik) | L12: =(M6+M7)*M8/1000000 -> 0.09 | M12: m2 | N12: =IF(L9="Kątownik",L12*M10,0.0001) -> 0.576 | O12: kg
E13: Profil ramki K30 | F13: =((F6*2)+(F7*2))/1000 -> 1.88 | G13: mb | K13: powierzchnia blachy (ceownik) | L13: =((M7*2)+M6)*M8/1000000 -> 0.135 | M13: m2 | N13: =IF(L9="Ceownik",L13*M10,0.0001) -> 0.0001 | O13: kg
D21: KOD OPTIMA | E21: Zapotrzebowanie materiału | F21: ilość | H21: cena jedn. | I21: wartość | K21: KOD OPTIMA | L21: Zapotrzebowanie materiału | M21: ilość | O21: cena jedn. | P21: wartość | R21: cena blachy do sprzedaży
D22: NAROŻNIK-K20 | E22: Narożnik 20 | F22: =IF(OR(F6>1000,F7>1000),0.0001,4) -> 4 | G22: szt | H22: ='Ceny składowe'!C20 -> 0.27 | I22: =H22*F22 -> 1.08 | K22: BLACHA0,60X1500 | L22: blacha 0,6 | M22: =IF(M10=4.8,(N12+N13),0.0001) -> 0.0001 | N22: kg | O22: ='Ceny składowe'!C6 -> 4.3 | P22: =(M22*O22) -> 0.00043 | R22: =P22*2 -> 0.00086
D23: NAROŻNIK-K30 | E23: Narożnik 30 | F23: =IF(OR(F6>1000,F7>1000),4,0.0001) -> 0.0001 | G23: szt | H23: ='Ceny składowe'!C22 -> 0.75 | I23: =H23*F23 -> 7.5e-05 | K23: BLACHA0,80X1500 | L23: blacha 0,8 | M23: =IF(M10=6.4,(N12+N13),0.0001) -> 0.5761 | N23: kg | O23: ='Ceny składowe'!C7 -> 4.2 | P23: =(M23*O23) -> 2.41962 | R23: =P23*2 -> 4.83924
D24: PROFILRAMKI20-P | E24: Profil ramki K20 | F24: =IF(OR(F6>1000,F7>1000),0.0001,F12) -> 1.88 | G24: mb | H24: ='Ceny składowe'!C34 -> 1.89 | I24: =H24*F24 -> 3.5532 | O24: koszt wygięcia | P24: =O26 -> 2.8
D25: PROFILRAMKI30-P | E25: Profil ramki K30 | F25: =IF(OR(F6>1000,F7>1000),F13,0.0001) -> 0.0001 | G25: mb | H25: ='Ceny składowe'!C36 -> 2.92 | I25: =H25*F25 -> 0.000292
K26: koszt pracy | L26: =_xlfn.IFS( AND(L9="Kątownik", M8>=1000), 4, AND(L9="Kątownik", M8>=500), 3, AND(L9="Kątownik", M8<500), 2, AND(L9="Ceownik", M8>=1000), 6, AND(L9="Ceownik", M8>=500), 5, AND(L9="Ceownik", M8<500), 4 ) -> 4 | M26: min. | N26: ='Ceny składowe'!C94 -> 0.7 | O26: =L26*N26 -> 2.8
H27: Koszt materiału | I27: =SUM(I22:I26) -> 4.633567 | O27: materiał + praca | P27: =P22+P23+O26 -> 5.22005
H29: Cena H3 | I29: =I27*3.6 -> 16.680841 | O29: Cena | P29: =R22+R23+P24 -> 7.6401
H30: Narzut | I30: =(I29-I27)/I27 -> 2.6 | O30: Narzut | P30: =(P29-P27)/P27 -> 0.46360667

Sheet Przej_dach_okr
B3: Przejście dachowe okrągłe
B6: FI | C6: ='Cennik Produkcja '!E265 -> 315 | D6: mm
B7: L | C7: ='Cennik Produkcja '!D265 -> 500 | D7: mm
B8: A | C8: ='Cennik Produkcja '!D263 -> 435 | D8: mm
B9: B | C9: ='Cennik Produkcja '!E263 -> 435 | D9: mm
B11: Powirzchnia rury | C11: =(((C6*3.14)+7)*C7)/1000000 -> 0.49805 | D11: m2
B12: Powierzchnia kołnierza | C12: =(C8*C9)/1000000 -> 0.189225 | D12: m2
B13: Otwór w kołnierzu | C13: =((C6/2)^2*3.14)/1000000 -> 0.077891625 | D13: m2
B14: Powierzchnia połączenia czapy z rurą | C14: =(C6*3.14)*100/1000000+0.025 -> 0.12391 | D14: m2
B15: Powierzchnia całkowita | C15: =C11+(C12-C13)+C14 -> 0.73329337 | D15: m2
B17: Grubość blachy | C17: 0.6 | D17: 0.8
B18: Współczynnik | C18: 8
B20: Waga blachy 0,6 | C20: =(C11+C14)*C17*C18 -> 2.985408 | D20: kg
B21: Waga blachy 0,8 | C21: =(C12-C13)*D17*C18 -> 0.7125336 | D21: kg
A24: KOD OPTIMA | B24: Zapotrzebowanie materiału | C24: ilość | E24: cena jedn. | F24: wartość | G24: wartość rury | I24: Wartość rury
A25: BLACHA0,60X1500 | B25: Blacha 0,6 | C25: =C20 -> 2.985408 | D25: kg | E25: ='Ceny składowe'!C6 -> 4.3 | F25: =(C14*C17*C18)*E25 -> 2.5575024 | G25: =((C11*4.8)*E25)+J27+J28 -> 21.329752 | I25: drut do zgrzewarki liniowej | J25: ='Ceny składowe'!C79 -> 2.1 | K25: mb.
A26: BLACHA0,80X1500 | B26: Blacha 0,8 | C26: =C21 -> 0.7125336 | D26: kg | E26: ='Ceny składowe'!C7 -> 4.2 | F26: =E26*C26 -> 2.9926411 | I26: długość rury | J26: =C7/1000 -> 0.5 | K26: mb.
I27: Cena za drut | J27: =J26*J25 -> 1.05
E28: Razem koszt | F28: =F25+F26 -> 5.5501435 | I28: koszt pracy | J28: =IF(C7>10,10,0) -> 10
E30: Cena H3 | F30: =_xlfn.IFS( C6<125, F28*21.3+G25, C6<160, F28*21.8+G25, C6<200, F28*20+G25, C6<250, F28*20.4+G25, C6<315, F28*20.2+G25, C6<400, F28*20.5+G25, C6>=400, F28*24.5+G25 ) -> 135.10769
E31: Narzut | F31: =(F30-F28)/F28 -> 23.343099

Sheet Wyrzutnie
A4: Wyrzutnia dachowa typu C okrągła (Chińczyk)
A8: Średnica | B8: Masa | D8: Blacha kg | E8: Siatka | G8: Cena AJP H3 | H8: Marża
A9: 100 | B9: 0.8 | C9: kg | D9: =IF('Cennik Produkcja '!$D$277=Wyrzutnie!A9,B9,0) -> 0 | E9: =IF(D9>0,(A9*0.6)*(A9*3.14)*1.1/1000000,0) -> 0 | G9: 120 | H9: 15.45
A10: 125 | B10: 1.1 | C10: kg | D10: =IF('Cennik Produkcja '!$D$277=Wyrzutnie!A10,B10,0) -> 0 | E10: =IF(D10>0,(A10*0.6)*(A10*3.14)*1.1/1000000,0) -> 0 | G10: 130 | H10: 13.03
A11: 160 | B11: 1.5 | C11: kg | D11: =IF('Cennik Produkcja '!$D$277=Wyrzutnie!A11,B11,0) -> 0 | E11: =IF(D11>0,(A11*0.6)*(A11*3.14)*1.1/1000000,0) -> 0 | G11: 140 | H11: 10.71
A12: 200 | B12: 2 | C12: kg | D12: =IF('Cennik Produkcja '!$D$277=Wyrzutnie!A12,B12,0) -> 0 | E12: =IF(D12>0,(A12*0.6)*(A12*3.14)*1.1/1000000,0) -> 0 | G12: 160 | H12: 9.39
A13: 250 | B13: 2.6 | C13: kg | D13: =IF('Cennik Produkcja '!$D$277=Wyrzutnie!A13,B13,0) -> 0 | E13: =IF(D13>0,(A13*0.6)*(A13*3.14)*1.1/1000000,0) -> 0 | G13: 180 | H13: 8.1
A14: 300 | B14: 4 | C14: kg | D14: =IF('Cennik Produkcja '!$D$277=Wyrzutnie!A14,B14,0) -> 0 | E14: =IF(D14>0,(A14*0.6)*(A14*3.14)*1.1/1000000,0) -> 0 | G14: 220
A15: 315 | B15: 4.2 | C15: kg | D15: =IF('Cennik Produkcja '!$D$277=Wyrzutnie!A15,B15,0) -> 4.2 | E15: =IF(D15>0,(A15*0.6)*(A15*3.14)*1.1/1000000,0) -> 0.20563389 | G15: 240 | H15: 6.86
A16: 355 | B16: 4.9 | C16: kg | D16: =IF('Cennik Produkcja '!$D$277=Wyrzutnie!A16,B16,0) -> 0 | E16: =IF(D16>0,(A16*0.6)*(A16*3.14)*1.1/1000000,0) -> 0 | G16: 350 | H16: 5.6
A17: 400 | B17: 6.4 | C17: kg | D17: =IF('Cennik Produkcja '!$D$277=Wyrzutnie!A17,B17,0) -> 0 | E17: =IF(D17>0,(A17*0.6)*(A17*3.14)*1.1/1000000,0) -> 0 | G17: 400 | H17: 5.17
A18: 450 | B18: 8.5 | C18: kg | D18: =IF('Cennik Produkcja '!$D$277=Wyrzutnie!A18,B18,0) -> 0 | E18: =IF(D18>0,(A18*0.6)*(A18*3.14)*1.1/1000000,0) -> 0 | G18: 450 | H18: 4.33
A19: 500 | B19: 11 | C19: kg | D19: =IF('Cennik Produkcja '!$D$277=Wyrzutnie!A19,B19,0) -> 0 | E19: =IF(D19>0,(A19*0.6)*(A19*3.14)*1.1/1000000,0) -> 0 | G19: 500 | H19: 3.89
A20: 630 | B20: 16.9 | C20: kg | D20: =IF('Cennik Produkcja '!$D$277=Wyrzutnie!A20,B20,0) -> 0 | E20: =IF(D20>0,(A20*0.6)*(A20*3.14)*1.1/1000000,0) -> 0
A21: 710 | B21: 23.4 | C21: kg | D21: =IF('Cennik Produkcja '!$D$277=Wyrzutnie!A21,B21,0) -> 0 | E21: =IF(D21>0,(A21*0.6)*(A21*3.14)*1.1/1000000,0) -> 0
A22: 800 | B22: 27.1 | C22: kg | D22: =IF('Cennik Produkcja '!$D$277=Wyrzutnie!A22,B22,0) -> 0 | E22: =IF(D22>0,(A22*0.6)*(A22*3.14)*1.1/1000000,0) -> 0
C24: Waga | D24: =SUM(D9:D23) -> 4.2 | E24: =SUM(E9:E23) -> 0.20563389
A27: KOD OPTIMA | B27: Zapotrzebowanie materiału | C27: ilość | E27: cena jedn. | F27: wartość
A28: BLACHA0,60X1500 | B28: Blacha 0,6 | C28: =D24*1.4 -> 5.88 | D28: kg | E28: ='Ceny składowe'!C6 -> 4.3 | F28: =E28*C28 -> 25.284
A29: SIATKACASANET19X19 | B29: Siatka 19x19 | C29: =E24 -> 0.20563389 | D29: mb | E29: ='Ceny składowe'!C42 -> 17.2 | F29: =E29*C29 -> 3.5369029
E31: Razem koszt | F31: =SUM(F28:F30) -> 28.820903
A38: Wyrzutnia dachowa typu A CWD-A
I39: Wyrzutnia dachowa typu E WDQ-E
B42: A | C42: ='Cennik Produkcja '!D284 -> 215 | J42: A | K42: ='Cennik Produkcja '!D42 -> 400
B43: B | C43: ='Cennik Produkcja '!E284 -> 215 | J43: B | K43: ='Cennik Produkcja '!E42 -> 400
B44: L | C44: ='Cennik Produkcja '!D286 -> 400 | J44: C | K44: =K42*2+100 -> 900
J45: h | K45: =IF(K42<=250,660,IF(K42<=300,720,IF(K42<=400,890,IF(K42<=500,1060,IF(K42<=600,1200,IF(K42<=700,1400,IF(K42<=800,1540,IF(K42<=900,1700,IF(K42<=1000,1880,IF(K42<=1100,2000,IF(K42<=1200,2220,IF(K42<=1500,2520)))))))))))) -> 890
J46: h (bez stopy) | K46: =K45-200 -> 690
B47: Pole blachy obudowy | C47: =((C42+C42+C43+C43)*C44)/1000000-C49/2 -> 0.297775 | D47: m2 | J47: skos | K47: =((K44-(K42+50))/2)*2 -> 450
B48: Pole blachy daszku | C48: =(C42+(C42/3*1.3*2))*(C43+(C42/3*1.3*2))/1000000 -> 0.16106844 | D48: m2
B49: Pole siatki | C49: =(C42/3*1.5)*(C42+C42+C43+C43)/1000000 -> 0.09245 | D49: m2 | J49: Pole blachy obudowy | K49: =((((K44+K42+50)*(K46/2)/2)*4)+(K43*(K47*4)))/1000000 -> 1.6515 | L49: m2
B50: Ramka 20 | C50: =(C42+C42+C43+C43)/1000 -> 0.86 | D50: mb | J50: Pole blachy stopy | K50: =((K42*2)+(K43*2))*300/1000000 -> 0.48 | L50: m2
B51: Ramka 30 | C51: =C50 -> 0.86 | D51: mb | J51: Pole blachy okapnika | K51: =((K47-100)*2)*(K43+50)/1000000 -> 0.315 | L51: m2 0,8
J52: Pole siatki | K52: =(K42+65)*(K43+65)/1000000 -> 0.216225 | L52: m2
B53: Blacha 0,6 | C53: =(C47+C48)*4.8 -> 2.2024485 | D53: kg | J53: Ramka 20 | K53: =(K42+K42+K43+K43)/1000 -> 1.6 | L53: mb
B54: Blacha 0,8 | C54: =(C47+C48)*6.4 -> 2.936598 | D54: kg | J54: Ramka 30 | K54: =K53 -> 1.6 | L54: mb
J56: Blacha 0,6 | K56: =(K49+K50)*4.8 -> 10.2312 | L56: kg
J57: Blacha 0,8 | K57: =(K49+K50)*6.4 -> 13.6416 | L57: kg
A58: KOD OPTIMA | B58: Zapotrzebowanie materiału | C58: ilość | E58: cena jedn. | F58: Wartość
A59: BLACHA0,60X1500 | B59: blacha 0,6 | C59: =IF(OR(C42>1000,C43>1000),0.0001,C53) -> 2.2024485 | D59: kg | E59: ='Ceny składowe'!C6 -> 4.3 | F59: =C59*E59 -> 9.4705287
...

Sheet Podstawa PD
B3: Podstawa Dachowa okrąga PDI-O | K3: Podstawa dachowa prostokątna PDQ-B
B6: A | C6: ='Cennik Produkcja '!D251 -> 410 | D6: mb | K6: A kanał | L6: ='Cennik Produkcja '!$D$235 -> 800 | M6: mb
B7: B | C7: ='Cennik Produkcja '!E251 -> 410 | D7: mb | K7: B kanał | L7: ='Cennik Produkcja '!$E$235 -> 500 | M7: mb
B8: Fi | C8: ='Cennik Produkcja '!D249 -> 315 | D8: mb | K8: C Kołnierz | L8: =L6+360 -> 1160 | M8: mb
B9: L FI | C9: ='Cennik Produkcja '!E249 -> 200 | D9: mm | K9: D Kołnierz | L9: =L7+360 -> 860 | M9: mb
B10: L wygięcia | C10: 50 | D10: mm | K10: L Kanał | L10: ='Cennik Produkcja '!D237 -> 1500 | M10: mb
K11: Wygięcie | L11: 0.05 | M11: mb
B12: Powierzchnia czapy | C12: =((C6*C7)-(((C8/2)*(C8/2))*3.14))/1000000 -> 0.090208375 | D12: m2
B13: Powierzchnia połączenia czapy z rurą | C13: =(C8*3.14)*100/1000000+0.025 -> 0.12391 | D13: m2 | K13: Powierzchnia czapy | L13: =((L8*L9)-(L6*L7))/1000000 -> 0.5976 | O13: Powierzchnia kołnierza | P13: =L13+L15 -> 0.6178 | Q13: m2
B14: Powierzchnia rury | C14: =((C8*3.14)*C9)/1000000 -> 0.19782 | D14: m2 | O14: Powierzchnia kanału | P14: =(((L6+L7+L6+L7)*L10)/1000000)+0.0001 -> 3.9001 | Q14: m2
B15: Powierzchnia wygięcia | C15: =((C6+C7+C6+C7)*C10)/1000000 -> 0.082 | D15: m2 | K15: Powierzchnia wygięcia | L15: =((L8+L9+L8+L9)*L11)/10000 -> 0.0202 | M15: m2
K16: Ramka | L16: =((L6+L7+L6+L7)*2)/1000 -> 5.2 | M16: mb
B17: Powierzchnia całk | C17: =C12+C14+C15 -> 0.37002838 | D17: m2 | K17: Narożnik | L17: 8 | M17: szt. | O17: Dla kanłów poniżej 1000mm
O18: Waga 0,6 | P18: =P14*N22*L23 -> 18.72048 | Q18: kg
B19: Grubość Blachy | C19: 0.8 | D19: 0.6 | O19: Waga 0,8 | P19: =P13*L22*L23 -> 3.95392 | Q19: kg
B20: współczynnik | C20: 8 | K20: Powierzchnia całk | L20: =L13+P14+L15 -> 4.5179 | M20: m2
B22: Waga powierzchni c. | C22: =C19*C20*C17 -> 2.3681816 | D22: kg | K22: Grubość Blachy | L22: 0.8 | M22: mm | N22: 0.6 | O22: mm
C23: =C22/1000 -> 0.0023681816 | D23: T | K23: współczynnik | L23: 8
K25: Waga powierzchni c. Bl.0,8 | L25: =L20*L22*L23 -> 28.91456 | M25: kg
A26: KOD OPTIMA | B26: Zapotrzebowanie materiału | C26: ilość | E26: cena jedn. | F26: wartość
A27: BLACHA0,60X1500 | B27: Blacha 0,6 | C27: =(C13+C14)*D19*C20 -> 1.544304 | D27: kg | E27: ='Ceny składowe'!C6 -> 4.3 | F27: =E27*C27 -> 6.6405072
A28: BLACHA0,80X1500 | B28: Blacha 0,8 | C28: =(C12+C15)*C19*C20 -> 1.1021336 | D28: kg | E28: ='Ceny składowe'!C7 -> 4.2 | F28: =E28*C28 -> 4.6289611
E29: Razem koszt | F29: =SUM(F27:F28) -> 11.269468 | K29: KOD OPTIMA | L29: Zapotrzebowanie materiału | M29: ilość | O29: cena jedn. | P29: wartość
B30: Do poprawy | K30: BLACHA0,80X1500 | L30: Blacha | M30: =IF(OR(L6>1000,L7>1000),L25,P19) -> 3.95392 | N30: kg | O30: ='Ceny składowe'!C7 -> 4.2 | P30: =O30*M30 -> 16.606464
E31: Cena H3 | F31: =IF(C8<125,F29*14.5,IF(C8<160,F29*14.5,IF(C8<200,F29*13.2,IF(C8<250,F29*13.4,IF(C8<315,F29*13.1,IF(C8<400,F29*13.2,IF(C8>=400,F29*15.4))))))) -> 148.75698 | K31: BLACHA0,60X1500 | L31: Blacha | M31: =IF(OR(L6>1000,L7>1000),0.0001,P18) -> 18.72048 | N31: kg | O31: ='Ceny składowe'!C6 -> 4.3 | P31: =O31*M31 -> 80.498064
E32: Narzut | F32: =(F31-F29)/F29 -> 12.2 | K32: NAROŻNIK-K20 | L32: Narożniki | M32: =IF(OR(L6>1000,L7>1000),0.0001,8) -> 8 | N32: szt. | O32: ='Ceny składowe'!C20 -> 0.27 | P32: =O32*M32 -> 2.16
K33: NAROŻNIK-K30 | L33: Narożniki | M33: =IF(OR(L6>1000,L7>1000),8,0.0001) -> 0.0001 | N33: mb | O33: ='Ceny składowe'!C22 -> 0.75 | P33: =O33*M33 -> 7.5e-05
B34: Podstawa Dachowa okrąga PDI-O-I | C34: (Armaflex) | K34: PROFILRAMKI20-P | L34: Profil ramki | M34: =IF(OR(L6>1000,L7>1000),0.0001,L16) -> 5.2 | N34: mb | O34: ='Ceny składowe'!C34 -> 1.89 | P34: =O34*M34 -> 9.828
K35: PROFILRAMKI30-P | L35: Profil ramki | M35: =IF(OR(L6>1000,L7>1000),L16,0.0001) -> 0.0001 | N35: mb | O35: ='Ceny składowe'!C36 -> 2.92 | P35: =O35*M35 -> 0.000292
O36: Razem koszt | P36: =SUM(P30:P35) -> 109.09289
B37: A | C37: ='Cennik Produkcja '!D258 -> 555 | D37: mb
B38: B | C38: ='Cennik Produkcja '!E258 -> 555 | D38: mb | O38: Cena H3 | P38: =IF(L6<600,P36*6,IF(L6<1000,P36*6.2,IF(L6>=1000,P36*7.08))) -> 676.37595
B39: Fi | C39: ='Cennik Produkcja '!D256 -> 315 | D39: mb | O39: Narzut | P39: =(P38-P36)/P36 -> 5.2
B40: L FI | C40: ='Cennik Produkcja '!E256 -> 200 | D40: mm
B41: L wygięcia | C41: 50 | D41: mm
B43: Powierzchnia czapy | C43: =((C37*C38)-(((C39/2)*(C39/2))*3.14))/1000000 -> 0.23013338 | D43: m2
B44: Powierzchnia połączenia czapy z rurą | C44: =(C39*3.14)*100/1000000+0.025 -> 0.12391 | D44: m2
B45: Powierzchnia rury | C45: =((C39*3.14)*C40)/1000000 -> 0.19782 | D45: m2
B46: Powierzchnia wygięcia | C46: =((C37+C38+C37+C38)*C41)/1000000 -> 0.111 | D46: m2
B48: Powierzchnia całk | C48: =C43+C45+C46 -> 0.53895337 | D48: m2
...

Sheet Puszka filtracyjna
B3: Puszka filtracyjna prostokątna PFP | I3: Puszka filtracyjna okrągła PFO
B5: A szerokość | C5: ='Cennik Produkcja '!D340 -> 1200 | I5: A | J5: ='Cennik Produkcja '!D347 -> 400 | L5: 100 | M5: 95.676
B6: B wysokość | C6: ='Cennik Produkcja '!E340 -> 600 | I6: B | J6: ='Cennik Produkcja '!E347 -> 780 | L6: 125 | M6: 99.576
B7: L | C7: ='Cennik Produkcja '!D342 -> 600 | I7: L | J7: ='Cennik Produkcja '!D349 -> 150 | L7: 150 | M7: 106.092
I8: Otwór pod kolary | J8: ='Cennik Produkcja '!E349 -> 355 | L8: 160 | M8: 106.404
B9: Powierzchnia obudowy | C9: =((C5+C5+C6+C6)*C7/1000000) -> 2.16 | L9: 200 | M9: 116.568
B10: Powierzchnia prowadnicy filtra | C10: =95*(C5+C6+C6)/1000000 -> 0.228 | I10: Powierchnia kolarów | J10: =((J8*3.14*0.1)*2)/1000 -> 0.22294 | L10: 225 | M10: 108.66
I11: Powierzchnie bez otworu | J11: =((((J5*2)+(J6*2))*J7)+((J5*J6)*2))/1000000 -> 0.978 | L11: 250 | M11: 131.796
B12: Zamek | C12: 2 | I12: Powierzchnia prowadnicy filtra | J12: =95*(J5+J6+J6)/1000000 -> 0.1862 | L12: 315 | M12: 153.516
B13: Narożniki | C13: 8 | I13: Razem | J13: =J10+J11+J12 -> 1.38714 | L13: 355 | M13: 165.084
B14: Ramka | C14: =((C5+C6+C5+C6)*2)/1000 -> 7.2 | L14: 400 | M14: 183.876
I15: Blacha | J15: 0.6 | L15: 450 | M15: 231.108
B16: Blacha | C16: 0.6 | I16: Współczynnik | J16: 8 | L16: 500 | M16: 251.328
B17: Współczynnik | C17: 8
I18: Gramatura | J18: =(J13*J15*J16)*1.1 -> 7.3240992
B19: Gramatura | C19: =C17*C16*(C9+C10) -> 11.4624 | I19: Gramatura w T | J19: =J18/1000 -> 0.0073240992
B20: Gramatura w T | C20: =C19/1000 -> 0.0114624
A22: KOD OPTIMA | B22: Zapotrzebowanie materiału | C22: ilość | E22: cena jedn. | F22: wartość | H22: KOD OPTIMA | I22: Zapotrzebowanie materiału | J22: ilość | L22: cena jedn. | M22: wartość
A23: BLACHA0,60X1500 | B23: Blacha | C23: =C19 -> 11.4624 | D23: kg | E23: ='Ceny składowe'!C6 -> 4.3 | F23: =E23*C23 -> 49.28832 | H23: BLACHA0,60X1500 | I23: Blacha | J23: =J18 -> 7.3240992 | K23: kg | L23: ='Ceny składowe'!C6 -> 4.3 | M23: =L23*J23 -> 31.493627
A24: ZAWIASTAŚMOWY | B24: Taśma zawias | C24: =(1/1.7*C6)/1000 -> 0.35294118 | D24: szt. | E24: 3.22 | F24: =E24*C24 -> 1.1364706 | H24: ZAWIASTAŚMOWY | I24: Taśma zawias | J24: =(1/1.7*J6)/1000 -> 0.45882353 | K24: szt. | L24: ='Ceny składowe'!C44 -> 8.06 | M24: =L24*J24 -> 3.6981176
A25: NAROŻNIK-K20 | B25: Narożniki | C25: =IF(OR(C5>1000,C6>1000),0.0001,8) -> 0.0001 | D25: szt. | E25: 0.35 | F25: =E25*C25 -> 3.5e-05 | H25: KAUCZUK 10MM | I25: kauczuk 9mm (tylko rewizja) | J25: =J5*J7/1000000 -> 0.06 | K25: m2 | L25: ='Ceny składowe'!C13 -> 26.81 | M25: =L25*J25 -> 1.6086
A26: NAROŻNIK-K30 | B26: Narożniki | C26: =IF(OR(C5>1000,C6>1000),8,0.0001) -> 8 | D26: mb | E26: ='Ceny składowe'!C22 -> 0.75 | F26: =E26*C26 -> 6 | H26: ZAMEK GOEBEL 40/F | I26: Zamek Goebel 40/F ocynk | J26: =IF(J7<=350,2,4) -> 2 | K26: szt. | L26: ='Ceny składowe'!C48 -> 3.46 | M26: =J26*L26 -> 6.92
A27: PROFILRAMKI20-P | B27: Profil ramki | C27: =IF(OR(C5>1000,C6>1000),0.0001,C14) -> 0.0001 | D27: mb | E27: 3.39 | F27: =E27*C27 -> 0.000339
A28: PROFILRAMKI30-P | B28: Profil ramki | C28: =IF(OR(C5>1000,C6>1000),C14,0.0001) -> 7.2 | D28: mb | E28: ='Ceny składowe'!C36 -> 2.92 | F28: =E28*C28 -> 21.024
A29: ŚRUBA M6X20 SKRZYDELKOWA | B29: śruba motylkowa | C29: 4 | D29: szt. | E29: ='Ceny składowe'!C77 -> 0.6 | F29: =C29*E29 -> 2.4
L30: Razem koszt | M30: =SUM(M23:M26) -> 43.720344
E31: Razem koszt | F31: =SUM(F23:F30) -> 79.849165
L32: Cena H3 | M32: =M30*5.4 -> 236.08986
E33: Cena H3 | F33: =F31*5 -> 399.24582 | L33: Narzut | M33: =(M32-M30)/M30 -> 4.4
E34: Narzut | F34: =(F33-F31)/F31 -> 4

Sheet Przepustnice
B3: Przepustnica wielopłaszczyznowa | I3: SMAY plus 10%
I4: PWII Przepustnica Wielopłaszczyznowa - 08.04.2026
B5: Szerokość B | C5: ='Cennik Produkcja '!D6 -> 350 | D5: mm | F5: koła/osie/łożyska | K5: wysokość H [mm]
B6: Wysokość H | C6: ='Cennik Produkcja '!E6 -> 250 | D6: mm | E6: =C6/100 -> 2.5 | F6: =ROUNDDOWN(E6,0.1) -> 2 | J6: X | K6: 100 | L6: 200 | M6: 400 | N6: 600 | O6: 800 | P6: 1000 | Q6: 1200 | R6: 1400 | S6: 1600 | T6: 1800 | U6: 2000 | V6: 2200
B7: typ | C7: ='Cennik Produkcja '!D8 -> B | I7: szerokość B [mm] | J7: 100 | K7: =K8-(K9-K8) -> 156.167 | L7: =L8-(L9-L8) -> 184.954 | M7: =M8-(M9-M8) -> 213.741 | N7: =N8-(N9-N8) -> 244.002 | O7: =O8-(O9-O8) -> 273.306 | P7: =P8-(P9-P8) -> 301.488 | Q7: =Q8-(Q9-Q8) -> 332.805 | R7: =R8-(R9-R8) -> 362.098 | ... U7: =U8-(U9-U8) -> 553.674 | V7: =(U7-T7)+U7 -> 583.704
J8: 200 | K8: =L8-(M8-L8) -> 162.459 | L8: 205.403 | M8: 248.347 | N8: 291.797 | O8: 334.741 | P8: 377.674 | Q8: 421.652 | R8: 464.596 | S8: 610.841 | T8: 654.577 | U8: 698.313 | V8: =(U8-T8)+U8 -> 742.049
B9: Ramka | C9: =(((C5+C6)*2)/1000)*2 -> 2.4 | D9: mb | J9: 400 | K9: =L9-(M9-L9) -> 168.751 | L9: 225.852 | M9: 282.953 | N9: 339.592 | O9: 396.176 | P9: 453.86 | Q9: 510.499 | R9: 567.094 | S9: 728.068 | T9: 785.51 | U9: 842.952 | V9: =(U9-T9)+U9 -> 900.394
B10: Płyta gładka (blacha ocynk) | C10: =((C5+30)*175)*2/1000000 -> 0.133 | D10: m2 | J10: 600 | K10: =L10-(M10-L10) -> 176.44 | L10: 246.741 | M10: 317.042 | N10: 387.332 | O10: 458.711 | P10: 529.001 | Q10: 599.302 | R10: 669.592 | S10: 845.35 | T10: 916.509 | U10: 987.602 | V10: =(U10-T10)+U10 -> 1058.695
B11: Przedłużenie pióra (wymiar niepełny) | C11: =IF(E11>0,F11) -> 0.091 | D11: m2 | E11: =MOD(E6,1) -> 0.5 | F11: =IF(E11<0.5,(0.8+(E11*2))*C5/10000,IF(E11>=0.5,((0.8+E11)*C5)*2)/10000) -> 0.091 | J11: 800 | K11: =L11-(M11-L11) -> 183.139 | L11: 267.135 | M11: 351.131 | N11: 436.15 | O11: 520.157 | P11: 604.098 | Q11: 688.094 | R11: 772.035 | S11: 962.643 | T11: 1047.442 | U11: 1132.241 | V11: =(U11-T11)+U11 -> 1217.04
B12: obudowa kół przy Belimo | C12: =IF(C7="B",0.2*C6)/1000 -> 0.05 | D12: m2 | E12: =IF(OR(C5>=1500,C6>=1400),C12*2,C12) -> 0.05 | F12: m2 | J12: 1000 | K12: =L12-(M12-L12) -> 188.793 | L12: 287.518 | M12: 386.243 | N12: 483.956 | O12: 581.592 | P12: 679.25 | Q12: 805.046 | R12: 902.748 | S12: 1108.096 | T12: 1206.535 | U12: 1305.04 | V12: =(U12-T12)+U12 -> 1403.545
J13: 1200 | K13: =L13-(M13-L13) -> 197.637 | L13: 308.99 | M13: 420.343 | N13: 531.696 | O13: 643.038 | P13: 782.54 | Q13: 922.042 | R13: 1033.406 | S13: 1253.527 | T13: 1365.683 | U13: 1477.828 | V13: =(U13-T13)+U13 -> 1589.973
B14: Blacha 0,6 | C14: =(C10+C11)*4.8 -> 1.0752 | D14: kg | J14: 1400 | K14: =L14-(M14-L14) -> 204.424 | L14: 329.428 | M14: 454.432 | N14: 579.425 | O14: 704.484 | P14: 857.637 | Q14: 1010.845 | R14: 1135.838 | S14: 1370.765 | T14: 1496.616 | U14: 1622.478 | V14: =(U14-T14)+U14 -> 1748.34
B15: blacha 0,6 obudowa belimo | C15: =E12*4.8 -> 0.24 | D15: kg | J15: 1600 | K15: =L15-(M15-L15) -> 278.091 | L15: 450.142 | M15: 622.193 | N15: 794.189 | O15: 966.185 | P15: 1168.101 | Q15: 1370.017 | R15: 1542.013 | S15: 1837.583 | T15: 2010.437 | U15: 2183.346 | V15: =(U15-T15)+U15 -> 2356.255
B16: Blacha 0,8 | C16: =(C10+C11)*6.4 -> 1.4336 | D16: kg | J16: 1800 | K16: =L16-(M16-L16) -> 285.23 | L16: 471.79 | M16: 658.35 | N16: 844.844 | O16: 1031.404 | P16: 1247.818 | Q16: 1464.188 | R16: 1650.737 | S16: 1961.949 | T16: 2149.367 | U16: 2336.774 | V16: =(U16-T16)+U16 -> 2524.181
J17: 2000 | K17: =L17-(M17-L17) -> 292.369 | L17: 493.427 | M17: 694.485 | N17: 895.554 | O17: 1096.557 | P17: 1327.48 | Q17: 1558.403 | R17: 1759.461 | S17: 2086.381 | T17: 2288.297 | U17: 2490.213 | V17: =(U17-T17)+U17 -> 2692.129
A18: KOD OPTIMA | B18: Zapotrzebowanie materiału | C18: ilość | E18: cena jedn. | F18: wartość | J18: 2200 | K18: =L18-(M18-L18) -> 299.508 | L18: =(L17-L16)+L17 -> 515.064 | M18: =(M17-M16)+M17 -> 730.62 | N18: =(N17-N16)+N17 -> 946.264 | O18: =(O17-O16)+O17 -> 1161.71 | P18: =(P17-P16)+P17 -> 1407.142 | Q18: =(Q17-Q16)+Q17 -> 1652.618 | R18: =(R17-R16)+R17 -> 1868.185 | S18: =(S17-S16)+S17 -> 2210.813 | ... U18: =(U17-U16)+U17 -> 2643.652 | V18: =(U18-T18)+U18 -> 2860.077
A19: PROFILPRZEPUSTNICAWILOPŁ | B19: Profil przepustnicy | C19: =F6*(C5/1000) -> 0.7 | D19: mb | E19: ='Ceny składowe'!C40 -> 22.9 | F19: =C19*E19 -> 16.03 | J19: 2400 | K19: =L19-(M19-L19) -> 306.64 | L19: 536.7 | M19: 766.76 | N19: 996.97 | O19: 1226.87 | P19: 1486.8 | Q19: 1746.84 | R19: 1976.92 | S19: 2335.24 | T19: 2566.16 | U19: 2797.09 | V19: =(U19-T19)+U19 -> 3028.02
A20: QPL-8 | B20: Łożysko | C20: =IF(C5<1500,F6*2,0.0001)+IF(C5>=1500<2000,F6*2,0.0001)+IF(C5>=2000,F6*4,0.0001) -> 4.0002 | D20: szt | E20: ='Ceny składowe'!C19 -> 0.55 | F20: =C20*E20 -> 2.20011 | J20: 2600 | K20: =(K19-K18)+K19 -> 313.772 | L20: =(L19-L18)+L19 -> 558.336 | M20: =(M19-M18)+M19 -> 802.9 | N20: =(N19-N18)+N19 -> 1047.676 | O20: =(O19-O18)+O19 -> 1292.03 | P20: =(P19-P18)+P19 -> 1566.458 | Q20: =(Q19-Q18)+Q19 -> 1841.062 | R20: =(R19-R18)+R19 -> 2085.655 | ... U20: =(U19-U18)+U19 -> 2950.528
A21: QOTK | B21: Oś krótka | C21: =IF(OR(C5>=1500,C6>=1400),0.0001,F6) -> 2 | D21: szt | E21: ='Ceny składowe'!C29 -> 0.45 | F21: =C21*E21 -> 0.9
A22: QOTD | B22: Oś długa | C22: =C31 -> 2 | D22: szt | E22: ='Ceny składowe'!C28 -> 0.57 | F22: =C22*E22 -> 1.14
A23: ZAMEDOPRZEPUSTNIC | B23: Zamek | C23: =G23 -> 0.0001 | D23: szt | E23: ='Ceny składowe'!C47 -> 6.9 | F23: =E23*C23 -> 0.00069 | G23: =IF(C7="B",0.0001,IF(C7="R",1,IF(C7=0,1))) -> 0.0001
A24: QSBŚCIANKABOCZNA | B24: Płyta boczna QSB | C24: =IF(C5>2000,C6/1000*4,C6/1000*2) -> 0.5 | D24: mb | E24: ='Ceny składowe'!C32 -> 10.5 | F24: =E24*C24 -> 5.25 | J24: Znalezienie pozycji w tabeli
A25: BLACHA0,60X1500 | B25: blacha 0,6 | C25: =G25+C15 -> 1.3152 | D25: kg | E25: ='Ceny składowe'!C6 -> 4.3 | F25: =E25*C25 -> 5.65536 | G25: =IF(OR(C5>1000,C6>1000),0.0001,C14) -> 1.0752 | H25: kg | J25: Pozycja kolumny (szer) | K25: =MATCH(C5, $J$7:$J$20, 1) -> 2 | R25: Zależności | S25: Szerokość
A26: BLACHA0,80X1500 | B26: blacha 0,8 | C26: =IF(OR(C5>1000,C6>1000),C16,0.0001) -> 0.0001 | D26: kg | E26: ='Ceny składowe'!C7 -> 4.2 | F26: =E26*C26 -> 0.00042 | J26: Pozycja wiersza (wys.) | K26: =MATCH(C6, $K$6:$V$6, 1) -> 2 | S26: od/do | T26: od | U26: pow.
A27: PROFILRAMKI20-P | B27: Profil ramki 20 | C27: =IF(OR(C5>1000,C6>1000),0.0001,C9) -> 2.4 | D27: mb | E27: ='Ceny składowe'!C34 -> 1.89 | F27: =E27*C27 -> 4.536 | J27: Pobranie 4 cen "sąsiadujących" | L27: wymiary graniczne | S27: 200-1499 | T27: 1500-2000 | U27: 2000
A28: NAROŻNIK-K20 | B28: Narożniki 20 | C28: =IF(OR(C5>1000,C6>1000),0.0001,8) -> 8 | D28: szt | E28: ='Ceny składowe'!C20 -> 0.27 | F28: =E28*C28 -> 2.16 | J28: Cena lewa góra | K28: =INDEX($K$7:$V$20, K25, K26) -> 205.403 | L28: szer_mniejsza (x1) | M28: =INDEX($J$7:$J$20, K25) -> 200 | R28: Koło zębate | S28: 1 rząd | T28: 2 rzędy | U28: 3 rzędy
A29: PROFILRAMKI30-P | B29: Profil ramki 30 | C29: =IF(OR(C5>1000,C6>1000),C9,0.0001) -> 0.0001 | D29: mb | E29: ='Ceny składowe'!C36 -> 2.92 | F29: =E29*C29 -> 0.000292 | J29: Cena prawa góra | K29: =INDEX($K$7:$V$20, K25, K26+1) -> 248.347 | L29: Szer_większa (x2) | M29: =INDEX($J$7:$J$20, K25 + 1) -> 400 | R29: Łożysko | S29: 1 rząd | T29: 2 rzędy | U29: 4 rzędy
A30: NAROŻNIK-K30 | B30: Narożniki 30 | C30: =IF(OR(C5>1000,C6>1000),8,0.0001) -> 0.0001 | D30: szt | E30: ='Ceny składowe'!C22 -> 0.75 | F30: =E30*C30 -> 7.5e-05 | J30: Cena lewa dół | K30: =INDEX($K$7:$V$20, K25+1, K26) -> 225.852 | L30: wys_mniejsza (y1) | M30: =INDEX($K$6:$V$6, K26) -> 200 | R30: Oś krótka | S30: 1 rząd | T30: 0 | U30: 0
A31: KOŁOZĘBATE | B31: Koło zębate | C31: =IF(C5<1500,F6)+IF(C5>=1500,F6*2)+IF(C5>=2000,F6)+H31 -> 2 | D31: szt | E31: ='Ceny składowe'!C18 -> 1.06 | F31: =E31*C31 -> 2.12 | G31: =IF(C6>=1400,F6) -> FALSE | H31: =IF(AND(C5>=1500,C6>=1500),0,G31) -> FALSE | J31: Cena prawa dół | K31: =INDEX($K$7:$V$20, K25+1, K26+1) -> 282.953 | L31: wys_wieksza (y2) | M31: =INDEX($K$6:$V$6, K26 + 1) -> 400 | R31: Oś długa | S31: 1 rząd | T31: 2 rzędy | U31: 3 rzędy
A32: OŚNAPĘDU 10X150 | B32: Oś napędu | C32: =G32 -> 1 | D32: szt | E32: ='Ceny składowe'!C30 -> 1.9 | F32: =E32*C32 -> 1.9 | G32: =IF(C7="B",1,IF(C7="R",0.0001,IF(C7=0,0.0001))) -> 1 | J32: Generowanie ceny | R32: Zamek | S32: 1 | T32: 1 | U32: 1
J33: Cena szer dół | K33: =K28 + (K30 - K28) * ((C5 - M28) / (M29 - M28)) -> 220.73975 | R33: Os napędu | S33: 1 | T33: 1 | U33: 1+iość koł 1 rząd
J34: Cena szer góra | K34: =K29 + (K31 - K29) * ((C5 - M28) / (M29 - M28)) -> 274.3015 | R34: Płyta boczna QSB | S34: 2 | T34: 2 | U34: 4
C35: dod. za Belimo | E35: koszt materiału | F35: =SUM(F19:F33) -> 41.892947 | J35: Wynik finalny | K35: =K33 + (K34 - K33) * ((C6 - M30) / (M31 - M30)) -> 234.13019 | R35: Płyta gładka (blacha ocynk) | S35: 2 | T35: 2 | U35: 2
A36: koszt pracy | B36: =_xlfn.IFS( C6<=400, 30, C6<=600, 45, C6<=900, 60, C6<=1200, 80, C6<=1400, 100, C6<=1600, 120, C6<=1800, 140, C6<=2000, 160 ) -> 30 | C36: =IF(AND(C5>=1500,C6>=1400),8,IF(AND(C5>=1500,C6<1400),8,IF(AND(C5<1500,C6>=1400),8,IF(AND(C5<1500,C6<1400),5)))) -> 5 | D36: min. | E36: ='Ceny składowe'!C94 -> 0.7 | F36: =(B36+C36)*E36 -> 24.5
E37: materiał + praca | F37: =F35+F36 -> 66.392947
E39: Cena | F39: =K35 -> 234.13019
E40: Narzut | F40: =(F39-F37)/F37 -> 2.5264316
B43: Przepustnica jednopłaszczyznowa
B45: Szerokość B | C45: ='Cennik Produkcja '!D10 -> 250 | D45: mm
B46: Wysokość H | C46: ='Cennik Produkcja '!E10 -> 200 | D46: mm
...

Sheet Wywietrzak cylindryczny
B1: Wywietrzak cylindryczny
A2: średnica | B2: masa | E2: Cena AJP H3 | F2: Marża
A3: 100 | B3: 1 | C3: kg | D3: =IF('Cennik Produkcja '!$D$270='Wywietrzak cylindryczny'!A3,'Wywietrzak cylindryczny'!B3,0) -> 0 | E3: 228.71 | F3: 32.68
A4: 125 | B4: 1.4 | C4: kg | D4: =IF('Cennik Produkcja '!$D$270='Wywietrzak cylindryczny'!A4,'Wywietrzak cylindryczny'!B4,0) -> 0 | E4: 243.86 | F4: 24.97
A5: 160 | B5: 2 | C5: kg | D5: =IF('Cennik Produkcja '!$D$270='Wywietrzak cylindryczny'!A5,'Wywietrzak cylindryczny'!B5,0) -> 0 | E5: 266.85 | F5: 19.08
A6: 200 | B6: 3.1 | C6: kg | D6: =IF('Cennik Produkcja '!$D$270='Wywietrzak cylindryczny'!A6,'Wywietrzak cylindryczny'!B6,0) -> 3.1 | E6: 295.9 | F6: 13.51
A7: 250 | B7: 5 | C7: kg | D7: =IF('Cennik Produkcja '!$D$270='Wywietrzak cylindryczny'!A7,'Wywietrzak cylindryczny'!B7,0) -> 0 | E7: 342.48 | F7: 9.35
A8: 315 | B8: 8.2 | C8: kg | D8: =IF('Cennik Produkcja '!$D$270='Wywietrzak cylindryczny'!A8,'Wywietrzak cylindryczny'!B8,0) -> 0 | E8: 414.14 | F8: 6.57
A9: 355 | B9: 10.5 | C9: kg | D9: =IF('Cennik Produkcja '!$D$270='Wywietrzak cylindryczny'!A9,'Wywietrzak cylindryczny'!B9,0) -> 0 | E9: 663.77 | F9: 9.2
A10: 400 | B10: 13.9 | C10: kg | D10: =IF('Cennik Produkcja '!$D$270='Wywietrzak cylindryczny'!A10,'Wywietrzak cylindryczny'!B10,0) -> 0 | E10: 734.11 | F10: 7.55
A11: 450 | B11: 15.7 | C11: kg | D11: =IF('Cennik Produkcja '!$D$270='Wywietrzak cylindryczny'!A11,'Wywietrzak cylindryczny'!B11,0) -> 0 | E11: 843.34 | F11: 7.64
A12: 500 | B12: 19.9 | C12: kg | D12: =IF('Cennik Produkcja '!$D$270='Wywietrzak cylindryczny'!A12,'Wywietrzak cylindryczny'!B12,0) -> 0 | E12: 1012.17 | F12: 7.22
A13: 630 | B13: 38.4 | C13: kg | D13: =IF('Cennik Produkcja '!$D$270='Wywietrzak cylindryczny'!A13,'Wywietrzak cylindryczny'!B13,0) -> 0 | E13: 1593.08 | F13: 5.93
A14: 710 | B14: 51 | C14: kg | D14: =IF('Cennik Produkcja '!$D$270='Wywietrzak cylindryczny'!A14,'Wywietrzak cylindryczny'!B14,0) -> 0 | E14: 0
A15: 800 | B15: 63.6 | C15: kg | D15: =IF('Cennik Produkcja '!$D$270='Wywietrzak cylindryczny'!A15,'Wywietrzak cylindryczny'!B15,0) -> 0 | E15: 0
C17: Waga | D17: =SUM(D3:D16) -> 3.1
A21: KOD OPTIMA | B21: Zapotrzebowanie materiału | C21: ilość | E21: cena jedn. | F21: wartość
A22: BLACHA0,60X1500 | B22: Blacha | C22: =D17 -> 3.1 | D22: kg | E22: ='Ceny składowe'!C6 -> 4.3 | F22: =C22*E22 -> 13.33
A23: NITZRYWALNY 4/6 | B23: nit | C23: =IF('Cennik Produkcja '!D270<=125,6,IF('Cennik Produkcja '!D270<=250,8,IF('Cennik Produkcja '!D270>=315,12)))/681 -> 0.01174743 | D23: kg | E23: ='Ceny składowe'!C58 -> 17.9 | F23: =C23*E23 -> 0.210279

Sheet Czerpnia ścienna
B2: czerpnia ścienna CWS | J2: marża | K2: Cena | L2: A (szerokość) | M2: B (wysokość) | N2: średnia sym.
J3: 2.655 | K3: =ROUND(F21*(1+J3),2) -> 69.35 | L3: =IF(C4<=250,K3,0) -> 69.35 | M3: =IF(C5<=250,K3,0) -> 69.35 | N3: =IF(AND(L3>0,M3>0),L3) -> 69.35
B4: Szerokość B | C4: ='Cennik Produkcja '!D16 -> 250 | D4: mm | J4: 2.229 | K4: =ROUND(F21*(1+J4),2) -> 61.27 | L4: =IF(AND(C4<=300,C4>250),K4,0) -> 0 | M4: =IF(AND(C5<=300,C5>250),K4,0) -> 0 | N4: =IF(AND(L4>0,M4>0),L4) -> FALSE
B5: Wysokość H | C5: ='Cennik Produkcja '!E16 -> 150 | D5: mm | J5: 1.8498 | K5: =ROUND(F21*(1+J5),2) -> 54.07 | L5: =IF(AND(C4<=400,C4>300),K5,0) -> 0 | M5: =IF(AND(C5<=400,C5>300),K5,0) -> 0 | N5: =IF(AND(L5>0,M5>0),L5) -> FALSE
J6: 1.7068 | K6: =ROUND(F21*(1+J6),2) -> 51.36 | L6: =IF(AND(C4<=500,C4>400),K6,0) -> 0 | M6: =IF(AND(C5<=500,C5>400),K6,0) -> 0 | N6: =IF(AND(L6>0,M6>0),L6) -> FALSE
B7: powierzchnia | C7: =(C4*C5)/1000000 -> 0.0375 | D7: m2 | J7: 1.521 | K7: =ROUND(F21*(1+J7),2) -> 47.83 | L7: =IF(AND(C4<=600,C4>500),K7,0) -> 0 | M7: =IF(AND(C5<=600,C5>500),K7,0) -> 0 | N7: =IF(AND(L7>0,M7>0),L7) -> FALSE
J8: 1.462 | K8: =ROUND(F21*(1+J8),2) -> 46.72 | L8: =IF(AND(C4<=700,C4>600),K8,0) -> 0 | M8: =IF(AND(C5<=700,C5>600),K8,0) -> 0 | N8: =IF(AND(L8>0,M8>0),L8) -> FALSE
J9: 1.3712 | K9: =ROUND(F21*(1+J9),2) -> 44.99 | L9: =IF(AND(C4<=800,C4>700),K9,0) -> 0 | M9: =IF(AND(C5<=800,C5>700),K9,0) -> 0 | N9: =IF(AND(L9>0,M9>0),L9) -> FALSE
A10: KOD OPTIMA | B10: Zapotrzebowanie materiału | C10: ilość | E10: cena jedn. | F10: wartość | J10: 1.3304 | K10: =ROUND(F21*(1+J10),2) -> 44.22 | L10: =IF(AND(C4<=900,C4>800),K10,0) -> 0 | M10: =IF(AND(C5<=900,C5>800),K10,0) -> 0 | N10: =IF(AND(L10>0,M10>0),L10) -> FALSE
A11: PROFILCZERPNIG | B11: Profil ramy czerpni gładki | C11: =(C4*2)/1000 -> 0.5 | D11: mb | E11: ='Ceny składowe'!C38 -> 10.9 | F11: =C11*E11 -> 5.45 | J11: 1.2572 | K11: =ROUND(F21*(1+J11),2) -> 42.83 | L11: =IF(AND(C4<=1000,C4>900),K11,0) -> 0 | M11: =IF(AND(C5<=1000,C5>900),K11,0) -> 0 | N11: =IF(AND(L11>0,M11>0),L11) -> FALSE
A12: PROFILCZERPNIP | B12: Profil ramy czerpni punktowany | C12: =(C5*2)/1000 -> 0.3 | D12: mb | E12: ='Ceny składowe'!C39 -> 11.9 | F12: =C12*E12 -> 3.57 | J12: 1.132 | K12: =ROUND(F21*(1+J12),2) -> 40.45 | L12: =IF(AND(C4<=1200,C4>1000),K12,0) -> 0 | M12: =IF(AND(C5<=1200,C5>1000),K12,0) -> 0 | N12: =IF(AND(L12>0,M12>0),L12) -> FALSE
A13: PROFILCZERP | B13: Profil łopatki czerpni | C13: =((C5/65)*C4)/1000 -> 0.57692308 | D13: mb | E13: ='Ceny składowe'!C33 -> 7.29 | F13: =C13*E13 -> 4.2057692 | J13: 1.101 | K13: =ROUND(F21*(1+J13),2) -> 39.87 | L13: =IF(AND(C4<=1500,C4>1200),K13,0) -> 0 | M13: =IF(AND(C5<=1500,C5>1200),K13,0) -> 0 | N13: =IF(AND(L13>0,M13>0),L13) -> FALSE
A14: NAROŻNIKCZERPNI | B14: Narożnik czerpni | C14: 4 | D14: szt | E14: ='Ceny składowe'!C24 -> 1.1 | F14: =C14*E14 -> 4.4 | J14: 1.1364 | K14: =ROUND(F21*(1+J14),2) -> 40.54 | L14: =IF(AND(C4<=1800,C4>1500),K14,0) -> 0 | M14: =IF(AND(C5<=1800,C5>1500),K14,0) -> 0 | N14: =IF(AND(L14>0,M14>0),L14) -> FALSE
A15: SIATKACASANET19X19 | B15: Siatka 1m | C15: =IF(AND(C4<=1000,C5>1000),C7,IF(AND(C4>1000,C5<=1000),C7,IF(AND(C4<=1000,C5<=1000),C7,IF(AND(C4>1000,C5>1000),0.0001)))) -> 0.0375 | D15: mb/m2 | E15: ='Ceny składowe'!C42 -> 17.2 | F15: =C15*E15 -> 0.645 | J15: 1.0805 | K15: =ROUND(F21*(1+J15),2) -> 39.48 | L15: =IF(AND(C4<=2000,C4>1800),K15,0) -> 0 | M15: =IF(AND(C5<=2000,C5>1800),K15,0) -> 0 | N15: =IF(AND(L15>0,M15>0),L15) -> FALSE
A16: SIATKACASANET19X19 L=1500 | B16: Siatka 1,5m | C16: =IF(AND(C4>1000,C5>1000),C7/1.4,IF(AND(C4<=1000,C5>1000),0.0001,IF(AND(C4>1000,C5<=1000),0.0001,IF(AND(C4<=1000,C5<=1000),0.0001)))) -> 0.0001 | D16: mb | E16: ='Ceny składowe'!C41 -> 24.39 | F16: =C16*E16 -> 0.002439 | J16: 1.03 | K16: =ROUND(F21*(1+J16),2) -> 38.52 | L16: =IF(C4>2000,K16,0) -> 0 | M16: =IF(C5>2000,K16,0) -> 0 | N16: =IF(AND(L16>0,M16>0),L16) -> FALSE
A17: NITZRYWALNY 4/6 | B17: Nit zrywalny 4/6 | C17: =8/681 -> 0.01174743 | D17: kg | E17: ='Ceny składowe'!C57 -> 15.91 | F17: =C17*E17 -> 0.18690162 | L17: =SUM(L3:L16) -> 69.35 | M17: =SUM(M3:M16) -> 69.35 | N17: =SUM(N3:N16) -> 69.35
A18: WKRĘT IMBUS 4,2X16 | B18: Wkręt samogwintujący pod imbus 4,2x19 (1000szt) | C18: =((C5/7)*4)/10000 -> 0.0085714286 | D18: op | E18: ='Ceny składowe'!C63 -> 38.1 | F18: =C18*E18 -> 0.32657143
K19: średnia sym. | L19: =L17 -> 69.35 | M19: =N17 -> 69.35 | N19: =AVERAGE(L17,M19) -> 69.35
E20: odpady | F20: 1.01 | K20: średnia asym. | L20: =L17 -> 69.35 | M20: =IF(AND(C4>=700,C5<=200),M17*(1-13%),IF(AND(C4<700,C5<=200),M17*(1-5%),IF(AND(C4>=700,C5<=400),M17*(1-6%),IF(AND(C4<700,C5<=400),M17,IF(AND(C4>=700,C5<=600),M17*(1+0.4%),IF(AND(C4<700,C5<=600),M17*(1+0.8%),IF(AND(C4>=700,C5<=1200),M17*(1+3.1%),IF(AND(C4<700,C5<=1200),M17*(1+2%),IF(AND(C4>=700,C5<=1500),M17*(1-1%),IF(AND(C4<700,C5<=1500),M17*(1-0.8%),IF(AND(C4>=700,C5<=2000),M17*(1+0.6%),IF(AND(C4<700,C5<=2000),M17*(1-0.5%),IF(AND(C4>=700,C5<=2500),M17*(1-0.4%),IF(AND(C4<700,C5<=2500),M17*(1-1%))))))))))))))) -> 65.8825 | N20: =AVERAGE(L20,M20) -> 67.61625
E21: Koszt materiału | F21: =SUM(F11:F18)*F20 -> 18.974548
B22: koszt pracy | C22: =IF(AND(C5<=400),30,IF(AND(C5<=600,C5>400),45,IF(AND(C5<=900,C5>600),60,IF(AND(C5<=1200,C5>900),80,IF(AND(C5<=1400,C5>1200),100,IF(AND(C5<=1600,C5>1400),120,IF(AND(C5<=1800,C5>1600),140,IF(AND(C5<=2000,C5>1800),160,IF(AND(C5>2000),180))))))))) -> 30 | D22: min. | E22: ='Ceny składowe'!C94 -> 0.7 | F22: =C22*E22 -> 21 | L22: Cena | M22: =IF(L17=M19,N19,N20) -> 69.35
E23: materiał + praca | F23: =F21+F22 -> 39.974548 | L23: Narzut | M23: =(M22-F23)/F23 -> 0.73485388
D25: Marża AJP 2019-03 (Optima) - PROPOZYCJA
F26: szerokość B [mm]
F27: 200 | G27: 300 | H27: 400 | I27: 500 | J27: 600 | K27: 700 | L27: 800 | M27: 900 | N27: 1000 | O27: 1200 | P27: 1500
D28: wysokość H [mm] | E28: 200 | F28: 3.5 | G28: 3 | H28: 2.5 | I28: 2 | J28: 2 | K28: 2 | L28: 2 | M28: 1.5 | N28: 1.5 | O28: 1.5 | P28: 1.25
E29: 300 | F29: 3.5 | G29: 3 | H29: 2.5 | I29: 2 | J29: 2 | K29: 2 | L29: 2 | M29: 1.5 | N29: 1.5 | O29: 1.5 | P29: 1.25
E30: 400 | F30: 3.5 | G30: 3 | H30: 2.5 | I30: 2 | J30: 2 | K30: 2 | L30: 2 | M30: 1.5 | N30: 1.5 | O30: 1.5 | P30: 1.25
E31: 500 | F31: 3.5 | G31: 3 | H31: 2.5 | I31: 2 | J31: 2 | K31: 2 | L31: 2 | M31: 1.5 | N31: 1.5 | O31: 1.5 | P31: 1.25
E32: 600 | F32: 3.5 | G32: 3 | H32: 2.5 | I32: 2 | J32: 2 | K32: 2 | L32: 2 | M32: 1.5 | N32: 1.5 | O32: 1.5 | P32: 1.25
E33: 700 | F33: 3.5 | G33: 3 | H33: 2.5 | I33: 2 | J33: 2 | K33: 2 | L33: 2 | M33: 1.5 | N33: 1.5 | O33: 1.5 | P33: 1.25
E34: 800 | F34: 3.5 | G34: 3 | H34: 2.5 | I34: 2 | J34: 2 | K34: 2 | L34: 2 | M34: 1.5 | N34: 1.5 | O34: 1.5 | P34: 1.25
E35: 900 | F35: 3.5 | G35: 3 | H35: 2.5 | I35: 2 | J35: 2 | K35: 2 | L35: 2 | M35: 1.5 | N35: 1.5 | O35: 1.5 | P35: 1.25
E36: 1000 | F36: 3.5 | G36: 3 | H36: 2.5 | I36: 2 | J36: 2 | K36: 2 | L36: 2 | M36: 1.5 | N36: 1.5 | O36: 1.5 | P36: 1.25
E37: 1200 | F37: 3.5 | G37: 3 | H37: 2.5 | I37: 2 | J37: 2 | K37: 2 | L37: 2 | M37: 1.5 | N37: 1.5 | O37: 1.5 | P37: 1.25
D41: plus 10%
D42: ZS- CZERPNIE ŚCIENNE - 10.04.2026
F43: wysokość H [mm]
D44: szerokość B [mm] | F44: 200 | G44: 400 | H44: 600 | I44: 800 | J44: 1000 | K44: 1200 | L44: 1400 | M44: 1600 | N44: 1800 | O44: 2000 | P44: 2200 | Q44: 2400 | R44: 2600
E45: 200 | F45: 70.081 | G45: 96.393 | H45: 122.683 | I45: 148.995 | J45: 175.956 | K45: 202.796 | L45: 229.79 | M45: 256.795 | N45: 283.8 | O45: 310.794 | P45: 337.799 | Q45: 364.804 | R45: 391.798
...

Sheet Tłumik prostokątny
B4: Tłumik prostokąt TP
M5: Zależności
B6: Wysokość H | C6: ='Cennik Produkcja '!E50 -> 300 | D6: mm | M6: Szerokość | P6: ilość kulis
B7: Szerokość B | C7: ='Cennik Produkcja '!D50 -> 1400 | D7: mm | M7: od | N7: do | P7: 100
B8: Długość - L | C8: ='Cennik Produkcja '!D52 -> 1000 | D8: mm | M8: 200 | N8: 300 | P8: 1
E9: Gramatura blachy kulis | M9: 301 | N9: 500 | P9: 2
B10: Ilość kulis 100 | C10: 4 | D10: szt | E10: =((((((C6*2)+(C8*2))*150)/1000000)*C10))*C25*C27 -> 9.984 | M10: 501 | N10: 700 | P10: 3
B11: Ilość kulis 150 | C11: 0 | D11: szt | E11: =(((((C6*2)+(C8*2))*200)/1000000)*C25)*C11 -> 0 | I11: koszt materiału | J11: =F43 -> 394.40445 | M11: 701 | N11: 900 | P11: 4
B12: Ilość kulis 200 | C12: =IF(C7<1001,0,IF(C7>2500,7,IF(C7>2000,6,IF(C7>1700,5,IF(C7>1300,4,IF(C7>1000,3)))))) -> 4 | D12: szt | E12: =(((((C6*2)+(C8*2))*250)/1000000)*C25*8)*C12 -> 16.64 | M12: 901 | N12: 1000 | P12: 5
B13: Powierzchnia kulis 100 | C13: =((C6*C8)*1)*C10/1000000 -> 1.2 | D13: m2 | H13: Cena sprzedaży AJP | I13: Cena sprzedaży PERŁA | J13: cena katalogowa | M13: Szerokość | P13: ilość kulis
B14: Powierzchnia kulis 150 | C14: =((C7*C8)*3)*C11/10000000 -> 0 | D14: m2 | F14: marża | G14: 2.4 | H14: =ROUND(J11*(1+G14),2) -> 1340.98 | I14: =ROUND(H14*0.8,2) -> 1072.78 | J14: =H14/0.6 -> 2234.9667 | M14: od | N14: do | P14: 200
B15: Powierzchnia kulis 200 | C15: =((C6*C8)*2)*C12/1000000 -> 2.4 | D15: m2 | F15: marża | G15: 4.14 | H15: =ROUND(J11*(1+G15),2) -> 2027.24 | I15: =ROUND(H15*0.86,2) -> 1743.43 | J15: =H15/0.6 -> 3378.7333 | M15: 1000 | N15: 1300 | P15: 3
B16: Długość ramek | C16: =(C6+C6+C7+C7)*2/1000 -> 6.8 | D16: mb | M16: 1301 | N16: 1700 | P16: 4
M17: 1701 | N17: 2000 | P17: 5
B18: Opas z blachy na kulisach 100 pow. | C18: =((C6+C6+C8+C8)*0.15)*C10/1000 -> 1.56 | D18: m2 | E18: =C18*C25*C27 -> 9.984 | F18: kg | M18: 2001 | N18: 2500 | P18: 6
B19: Opas z blachy na kulisach 150 pow. | C19: =((C6+C6+C8+C8)*0.2)*C11/1000 -> 0 | D19: m2 | E19: =C19*C25*C27 -> 0 | F19: kg | M19: 2501 | P19: 7
B20: Opas z blachy na kulisach 200 pow. | C20: =((C6+C6+C8+C8)*0.25)*C12/1000 -> 2.6 | D20: m2 | E20: =C20*C25*C27 -> 16.64 | F20: kg
B21: Powierzchnia kanału | C21: =(C6+C6+C7+C7)*C8/1000000 -> 3.4 | D21: m2 | E21: =C21*C26*C27 -> 21.76 | F21: kg
N22: 200 | O22: 300 | P22: 400 | Q22: 500 | R22: 600 | S22: 700 | T22: 800 | U22: 900 | V22: 1000 | W22: 1200 | X22: 1400 | Y22: 1600 | Z22: 1800 | AA22: 2000
B23: Całkowita pow blachy | C23: =SUM(C18:C21) -> 7.56 | D23: m2 | M23: 200 | N23: 1.6 | O23: 1.6 | P23: 1.4 | Q23: 1.4 | R23: 1.4 | S23: 1.4 | T23: 1.4 | U23: 1.05 | V23: 1.05 | W23: 1.05 | X23: 1.05 | Y23: 1.05 | Z23: 1.05 | AA23: 1.05
M24: 300 | N24: 1.6 | O24: 1.6 | P24: 1.4 | Q24: 1.4 | R24: 1.4 | S24: 1.4 | T24: 1.4 | U24: 1.05 | V24: 1.05 | W24: 1.05 | X24: 1.05 | Y24: 1.05 | Z24: 1.05 | AA24: 1.05
B25: Grubość blachy kulisy | C25: =IF(AND(C6<=800,C8<1000),0.6,IF(AND(C6<=800,C8>=1000),0.8,IF(AND(C6>800,C8<=1000),0.8,IF(AND(C6>800,C8>1000),0.8)))) -> 0.8 | D25: mm | M25: 400 | N25: 1.05 | O25: 1.05 | P25: 0.8 | Q25: 0.8 | R25: 0.8 | S25: 0.8 | T25: 0.8 | U25: 0.65 | V25: 0.65 | W25: 0.65 | X25: 0.65 | Y25: 0.65 | Z25: 0.65 | AA25: 0.65
B26: Grubość blachy kanału | C26: =IF(AND(C6<=800,C7<=800),0.6,IF(AND(C6<=800,C7>800),0.8,IF(AND(C6>800,C7<=800),0.8,IF(AND(C6>800,C7>800),0.8)))) -> 0.8 | D26: mm | M26: 500 | N26: 1.05 | O26: 1.05 | P26: 0.8 | Q26: 0.8 | R26: 0.8 | S26: 0.8 | T26: 0.8 | U26: 0.65 | V26: 0.65 | W26: 0.65 | X26: 0.65 | Y26: 0.65 | Z26: 0.65 | AA26: 0.65
B27: Współczynnik | C27: 8 | M27: 600 | N27: 1.05 | O27: 1.05 | P27: 0.8 | Q27: 0.8 | R27: 0.8 | S27: 0.8 | T27: 0.8 | U27: 0.65 | V27: 0.65 | W27: 0.65 | X27: 0.65 | Y27: 0.65 | Z27: 0.65 | AA27: 0.65
M28: 700 | N28: 1.05 | O28: 1.05 | P28: 0.8 | Q28: 0.8 | R28: 0.8 | S28: 0.8 | T28: 0.8 | U28: 0.65 | V28: 0.65 | W28: 0.65 | X28: 0.65 | Y28: 0.65 | Z28: 0.65 | AA28: 0.65
B29: Gramatura blachy | C29: =(8*C26*((C8/1000*2*(C6/1000+C7/1000))))+SUM(E10,E11,E12) -> 48.384 | D29: kg | M29: 800 | N29: 1.05 | O29: 1.05 | P29: 0.8 | Q29: 0.8 | R29: 0.8 | S29: 0.8 | T29: 0.8 | U29: 0.65 | V29: 0.65 | W29: 0.65 | X29: 0.65 | Y29: 0.65 | Z29: 0.65 | AA29: 0.65
B30: Gramatura | C30: =C29/1000 -> 0.048384 | D30: T | M30: 900 | N30: 1.05 | O30: 1.05 | P30: 0.65 | Q30: 0.65 | R30: 0.65 | S30: 0.65 | T30: 0.65 | U30: 0.65 | V30: 0.65 | W30: 0.65 | X30: 0.65 | Y30: 0.65 | Z30: 0.65 | AA30: 0.65
M31: 1000 | N31: 1.05 | O31: 1.05 | P31: 0.65 | Q31: 0.65 | R31: 0.65 | S31: 0.65 | T31: 0.65 | U31: 0.65 | V31: 0.65 | W31: 0.65 | X31: 0.65 | Y31: 0.65 | Z31: 0.65 | AA31: 0.65
M32: 1200 | N32: 1.05 | O32: 1.05 | P32: 0.65 | Q32: 0.65 | R32: 0.65 | S32: 0.65 | T32: 0.65 | U32: 0.65 | V32: 0.65 | W32: 0.65 | X32: 0.65 | Y32: 0.65 | Z32: 0.65 | AA32: 0.65
A33: KOD OPTIMA | B33: Zapotrzebowanie materiału | C33: ilość | E33: cena jedn. | F33: wartość | M33: 1500 | N33: 1.05 | O33: 1.05 | P33: 0.65 | Q33: 0.65 | R33: 0.65 | S33: 0.65 | T33: 0.65 | U33: 0.65 | V33: 0.65 | W33: 0.65 | X33: 0.65 | Y33: 0.65 | Z33: 0.65 | AA33: 0.65
A34: BLACHA0,80X1500 | B34: Blacha | C34: =IF(AND(C25=0.8,C26=0.6),E18+E19+E20,IF(AND(C25=0.8,C26=0.8),E18+E19+E20+E21,IF(AND(C25=0.6,C26=0.8),E21,IF(AND(C25=0.6,C26=0.6),0.0001)))) -> 48.384 | D34: kg | E34: ='Ceny składowe'!C7 -> 4.2 | F34: =E34*C34 -> 203.2128
A35: BLACHA0,60X1500 | B35: Blacha | C35: =IF(AND(C25=0.8,C26=0.6),E21,IF(AND(C25=0.8,C26=0.8),0.0001,IF(AND(C25=0.6,C26=0.8),E18+E19+E20,IF(AND(C25=0.6,C26=0.6),E18+E19+E20+E21)))) -> 0.0001 | D35: kg | E35: ='Ceny składowe'!C6 -> 4.3 | F35: =E35*C35 -> 0.00043
A36: KNAUFBD060/100/2000/1200 | B36: Wełna 100 welon dwustronny | C36: =C13+C14+C15 -> 3.6 | D36: m2 | E36: ='Ceny składowe'!C62 -> 45.8 | F36: =E36*C36 -> 164.88
A37: NAROŻNIK-K20 | B37: Narożniki | C37: =IF(OR(C6>1000,C7>1000),0.0001,8) -> 0.0001 | D37: szt. | E37: ='Ceny składowe'!C20 -> 0.27 | F37: =E37*C37 -> 2.7e-05
A38: PROFILRAMKI20-P | B38: Profil ramki | C38: =IF(OR(C6>1000,C7>1000),0.0001,C16) -> 0.0001 | D38: mb | E38: ='Ceny składowe'!C34 -> 1.89 | F38: =E38*C38 -> 0.000189
A39: PROFILRAMKI30-P | B39: Profil ramki | C39: =IF(OR(C6>1000,C7>1000),C16,0.0001) -> 6.8 | D39: mb | E39: ='Ceny składowe'!C36 -> 2.92 | F39: =E39*C39 -> 19.856
A40: NAROŻNIK-K30 | B40: Narożniki | C40: =IF(OR(C6>1000,C7>1000),8,0.0001) -> 8 | D40: mb | E40: ='Ceny składowe'!C22 -> 0.75 | F40: =E40*C40 -> 6
A41: SILIKON UNIWERSALNY STINGER | B41: Silikon | C41: 0.05 | D41: szt. | E41: ='Ceny składowe'!C78 -> 9.1 | F41: =E41*C41 -> 0.455
E43: Koszt materiału | F43: =SUM(F34:F41) -> 394.40445
E44: Cena sprzedaży | F44: =IF(AND(C7<=400,C6<400),F43*5.35,IF(AND(C7<=400,C6>=400),F43*4.5,IF(AND(C7<=600,C6<400),F43*5.33,IF(AND(C7<700,C6<400),F43*5.2,IF(AND(C7<=800,C6<400),F43*5.22,IF(AND(C7<=800,C6>=400),F43*4.43,IF(AND(C7<=1000,C6<400),F43*3.76,IF(AND(C7<=1000,C6>=400),F43*3.76,IF(AND(C7<=1200,C6<400),F43*3.24,IF(AND(C7<=1200,C6>=400),F43*3.24,IF(AND(C7<=1400,C6<400),F43*2.87,IF(AND(C7<=1400,C6>=400),F43*2.87,IF(AND(C7<=1800,C6<400),F43*3.21,IF(AND(C7<=1800,C6>=400),F43*3.21,IF(AND(C7>1800,C6<400),F43*2.88,IF(AND(C7>1800,C6>=400),F43*2.88)))))))))))))))) -> 1131.9408
...

Sheet Tłumik okrągły
B6: fi | C6: ='Cennik Produkcja '!D68 -> 400 | D6: mm | J6: fi spiro | K6: fi tłumika | L6: koszt spiro
B7: L | C7: ='Cennik Produkcja '!E68 -> 1200 | D7: mm | H7: =IF($D$8=J7,1,0) -> 0 | I7: SPIRO200P40 | J7: 200 | K7: 100 | L7: ='Kalkulacje spiro'!S16 -> 34.814292
B8: fi zewnętrzne | C8: =C6+'Cennik Produkcja '!D66*2 -> 500 | D8: =IF(C8=180,200,IF(C8=200,200,IF(C8=225,250,IF(C8=240,250,IF(C8=260,315,IF(C8=300,315,IF(C8=325,355,IF(C8=350,355,IF(C8=395,400,IF(C8=360,400,IF(C8=400,400,IF(C8=415,450,IF(C8=425,450,IF(C8=450,450,IF(C8=455,450,IF(C8=460,500,IF(C8=500,500,IF(C8=515,560,IF(C8=550,560,IF(C8=555,560,IF(C8=600,630,IF(C8=615,630,IF(C8=620,630,IF(C8=650,710,IF(C8=655,710,IF(C8=700,710,IF(C8=730,800,IF(C8=750,800,IF(C8=800,800,IF(C8=810,900,IF(C8=830,900))))))))))))))))))))))))))))))) -> 500 | H8: =IF($D$8=J8,1,0) -> 0 | I8: SPIRO250P45 | J8: 250 | K8: 125 | L8: ='Kalkulacje spiro'!S18 -> 45.049576
B9: Powierzchnia nypli | C9: =(((3.14*C6))*65)*2/1000000 -> 0.16328 | D9: m2 | E9: =C9*4.8 -> 0.783744 | F9: kg | H9: =IF($D$8=J9,1,0) -> 0 | I9: SPIRO250P45 | J9: 250 | K9: 160 | L9: ='Kalkulacje spiro'!S18 -> 45.049576
B10: Powierzchnia dekli | C10: =((3.14*(((C6+('Cennik Produkcja '!D66*2))/2)^2))*2)/1000000 -> 0.3925 | D10: m2 | E10: =C10*6.4 -> 2.512 | F10: kg | H10: =IF($D$8=J10,1,0) -> 0 | I10: SPIRO315P45 | J10: 315 | K10: 200 | L10: ='Kalkulacje spiro'!S20 -> 56.122409
B11: Powierzchnia płaszcza | C11: =(((C6+(2*'Cennik Produkcja '!D66))*3.14)*('Cennik Produkcja '!E68+30)/1000000) -> 1.9311 | D11: m2 | E11: =C11*4.8 -> 9.26928 | F11: kg | H11: =IF($D$8=J11,1,0) -> 0 | I11: SPIRO355P50 | J11: 355 | K11: 250 | L11: ='Kalkulacje spiro'!S21 -> 72.646555
B12: Powierzchnia siatki | C12: =(((C6+10)*3.14)*C7)/1000000 -> 1.54488 | D12: m2 | H12: =IF($D$8=J12,1,0) -> 0 | I12: SPIRO400P50 | J12: 400 | K12: 315 | L12: ='Kalkulacje spiro'!S22 -> 81.863826
B13: Powierzchnia wełny | C13: =(((C6+'Cennik Produkcja '!D66*2)*3.14)*C7)/1000000 -> 1.884 | D13: m2 | H13: =IF($D$8=J13,1,0) -> 0 | I13: SPIRO450P50 | J13: 450 | K13: 355 | L13: ='Kalkulacje spiro'!S23 -> 92.10193
H14: =IF($D$8=J14,1,0) -> 1 | I14: SPIRO500P60 | J14: 500 | K14: 400 | L14: ='Kalkulacje spiro'!S24 -> 119.09455
B15: Grubość blachy | C15: 0.6 | D15: 0.8 | H15: =IF($DC$8=J15,1,0) -> 0 | I15: SPIRO560P60 | J15: 560 | K15: 450 | L15: ='Kalkulacje spiro'!S25 -> 133.39132
B16: Współczynnik | C16: 8 | H16: =IF(D$8=J16,1,0) -> 0 | I16: SPIRO630P60 | J16: 630 | K16: 500 | L16: ='Kalkulacje spiro'!S26 -> 150.0492
H17: =IF($D$8=J17,1,0) -> 0 | I17: SPIRO710P60 | J17: 710 | K17: 630 | L17: ='Kalkulacje spiro'!S27 -> 169.07048
B18: Gramatura blachy | C18: =(C9+C11)*C15*C16 -> 10.053024 | D18: kg | H18: =IF($D$8=J18,1,0) -> 0 | I18: SPIRO800P60 | J18: 800 | K18: 710 | L18: ='Kalkulacje spiro'!S28 -> 190.60184
B19: Gramatura | C19: =C18/1000 -> 0.010053024 | D19: T | H19: =IF($D$8=J19,1,0) -> 0 | I19: SPIRO900P70 | J19: 900 | K19: 800 | L19: ='Kalkulacje spiro'!S29 -> 280.95436
A24: KOD OPTIMA | B24: Zapotrzebowanie materiału | C24: ilość | E24: cena jedn. | F24: wartość | I24: KOD OPTIMA | J24: Zapotrzebowanie materiału | K24: ilość | M24: cena jedn. | N24: wartość
A25: BLACHA0,60X1500 | B25: Blacha 0,6 | C25: =E9+E11 -> 10.053024 | D25: kg | E25: ='Ceny składowe'!C6 -> 4.3 | F25: =E25*C25 -> 43.228003 | I25: =VLOOKUP(1,H7:I20,2,FALSE) -> SPIRO500P60 | J25: Spiro | K25: =C7/3000 -> 0.4 | L25: mm | M25: =VLOOKUP(1,H7:L19,5,FALSE) -> 119.09455 | N25: =K25*M25 -> 47.637821
